{
 "cells": [
  {
   "cell_type": "code",
   "execution_count": null,
   "metadata": {},
   "outputs": [
    {
     "name": "stderr",
     "output_type": "stream",
     "text": [
      "2018-10-29 16:44:00,458 - telegram.ext.dispatcher - WARNING - A TelegramError was raised while processing the Update\n",
      "2018-10-29 16:44:00,465 - __main__ - WARNING - Update \"{'update_id': 580789194, 'callback_query': {'id': '451864592557242661', 'chat_instance': '8294903532009219515', 'message': {'message_id': 137, 'date': 1540808581, 'chat': {'id': 105207923, 'type': 'private', 'username': 'beisekenov', 'first_name': 'Ildar', 'last_name': 'Beisekenov'}, 'text': 'Services covered by Residence Life unit:', 'entities': [], 'caption_entities': [], 'photo': [], 'new_chat_members': [], 'new_chat_photo': [], 'delete_chat_photo': False, 'group_chat_created': False, 'supergroup_chat_created': False, 'channel_chat_created': False, 'from': {'id': 647382703, 'first_name': 'DSD bot', 'is_bot': True, 'username': 'nu_dsd_bot'}}, 'data': '1', 'from': {'id': 105207923, 'first_name': 'Ildar', 'is_bot': False, 'last_name': 'Beisekenov', 'username': 'beisekenov', 'language_code': 'en-US'}}}\" caused error \"Message is not modified\"\n",
      "2018-10-29 17:16:52,984 - telegram.ext.dispatcher - WARNING - A TelegramError was raised while processing the Update\n",
      "2018-10-29 17:16:52,986 - __main__ - WARNING - Update \"{'update_id': 580789202, 'message': {'message_id': 148, 'date': 1540811812, 'chat': {'id': 105207923, 'type': 'private', 'username': 'beisekenov', 'first_name': 'Ildar', 'last_name': 'Beisekenov'}, 'text': '/start', 'entities': [{'type': 'bot_command', 'offset': 0, 'length': 6}], 'caption_entities': [], 'photo': [], 'new_chat_members': [], 'new_chat_photo': [], 'delete_chat_photo': False, 'group_chat_created': False, 'supergroup_chat_created': False, 'channel_chat_created': False, 'from': {'id': 105207923, 'first_name': 'Ildar', 'is_bot': False, 'last_name': 'Beisekenov', 'username': 'beisekenov', 'language_code': 'en-US'}}}\" caused error \"urllib3 HTTPError ('Connection aborted.', ConnectionResetError(10054, 'An existing connection was forcibly closed by the remote host', None, 10054, None))\"\n",
      "2018-10-29 18:13:49,326 - telegram.vendor.ptb_urllib3.urllib3.connectionpool - WARNING - Retrying (Retry(total=2, connect=None, read=None, redirect=None)) after connection broken by 'ConnectTimeoutError(<telegram.vendor.ptb_urllib3.urllib3.connection.VerifiedHTTPSConnection object at 0x000000000611C0F0>, 'Connection to api.telegram.org timed out. (connect timeout=5.0)')': /bot647382703:AAE-w7ZRzGoOopTtpiaAF40qlkHapWnMvBU/getUpdates\n",
      "2018-10-29 18:14:08,170 - telegram.vendor.ptb_urllib3.urllib3.connectionpool - WARNING - Retrying (Retry(total=2, connect=None, read=None, redirect=None)) after connection broken by 'ConnectTimeoutError(<telegram.vendor.ptb_urllib3.urllib3.connectionpool.HTTPSConnectionPool object at 0x00000000060E4A58>, 'Connect timed out. (connect timeout=5.0)')': /bot647382703:AAE-w7ZRzGoOopTtpiaAF40qlkHapWnMvBU/getUpdates\n",
      "2018-10-29 18:14:13,318 - telegram.vendor.ptb_urllib3.urllib3.connectionpool - WARNING - Retrying (Retry(total=1, connect=None, read=None, redirect=None)) after connection broken by 'ConnectTimeoutError(<telegram.vendor.ptb_urllib3.urllib3.connectionpool.HTTPSConnectionPool object at 0x00000000060E4A58>, 'Connect timed out. (connect timeout=5.0)')': /bot647382703:AAE-w7ZRzGoOopTtpiaAF40qlkHapWnMvBU/getUpdates\n",
      "2018-10-29 18:14:18,462 - telegram.vendor.ptb_urllib3.urllib3.connectionpool - WARNING - Retrying (Retry(total=0, connect=None, read=None, redirect=None)) after connection broken by 'ConnectTimeoutError(<telegram.vendor.ptb_urllib3.urllib3.connectionpool.HTTPSConnectionPool object at 0x00000000060E4A58>, 'Connect timed out. (connect timeout=5.0)')': /bot647382703:AAE-w7ZRzGoOopTtpiaAF40qlkHapWnMvBU/getUpdates\n",
      "2018-10-29 18:14:35,324 - telegram.vendor.ptb_urllib3.urllib3.connectionpool - WARNING - Retrying (Retry(total=2, connect=None, read=None, redirect=None)) after connection broken by 'ConnectTimeoutError(<telegram.vendor.ptb_urllib3.urllib3.connection.VerifiedHTTPSConnection object at 0x0000000006141198>, 'Connection to api.telegram.org timed out. (connect timeout=5.0)')': /bot647382703:AAE-w7ZRzGoOopTtpiaAF40qlkHapWnMvBU/getUpdates\n",
      "2018-10-29 18:14:41,888 - telegram.vendor.ptb_urllib3.urllib3.connectionpool - WARNING - Retrying (Retry(total=1, connect=None, read=None, redirect=None)) after connection broken by 'ConnectTimeoutError(<telegram.vendor.ptb_urllib3.urllib3.connectionpool.HTTPSConnectionPool object at 0x00000000060E4A58>, 'Connect timed out. (connect timeout=5.0)')': /bot647382703:AAE-w7ZRzGoOopTtpiaAF40qlkHapWnMvBU/getUpdates\n",
      "2018-10-29 18:14:46,891 - telegram.vendor.ptb_urllib3.urllib3.connectionpool - WARNING - Retrying (Retry(total=0, connect=None, read=None, redirect=None)) after connection broken by 'ConnectTimeoutError(<telegram.vendor.ptb_urllib3.urllib3.connection.VerifiedHTTPSConnection object at 0x0000000006141278>, 'Connection to api.telegram.org timed out. (connect timeout=5.0)')': /bot647382703:AAE-w7ZRzGoOopTtpiaAF40qlkHapWnMvBU/getUpdates\n",
      "2018-10-29 20:03:52,615 - telegram.vendor.ptb_urllib3.urllib3.connectionpool - WARNING - Retrying (Retry(total=2, connect=None, read=None, redirect=None)) after connection broken by 'NewConnectionError('<telegram.vendor.ptb_urllib3.urllib3.connection.VerifiedHTTPSConnection object at 0x00000000061290F0>: Failed to establish a new connection: [Errno 11004] getaddrinfo failed')': /bot647382703:AAE-w7ZRzGoOopTtpiaAF40qlkHapWnMvBU/getUpdates\n",
      "2018-10-29 20:03:52,628 - telegram.vendor.ptb_urllib3.urllib3.connectionpool - WARNING - Retrying (Retry(total=1, connect=None, read=None, redirect=None)) after connection broken by 'NewConnectionError('<telegram.vendor.ptb_urllib3.urllib3.connection.VerifiedHTTPSConnection object at 0x0000000006129EB8>: Failed to establish a new connection: [Errno 11004] getaddrinfo failed')': /bot647382703:AAE-w7ZRzGoOopTtpiaAF40qlkHapWnMvBU/getUpdates\n",
      "2018-10-29 20:03:52,631 - telegram.vendor.ptb_urllib3.urllib3.connectionpool - WARNING - Retrying (Retry(total=0, connect=None, read=None, redirect=None)) after connection broken by 'NewConnectionError('<telegram.vendor.ptb_urllib3.urllib3.connection.VerifiedHTTPSConnection object at 0x0000000006129160>: Failed to establish a new connection: [Errno 11004] getaddrinfo failed')': /bot647382703:AAE-w7ZRzGoOopTtpiaAF40qlkHapWnMvBU/getUpdates\n",
      "2018-10-29 20:03:52,634 - telegram.ext.updater - ERROR - Error while getting Updates: urllib3 HTTPError HTTPSConnectionPool(host='api.telegram.org', port=443): Max retries exceeded with url: /bot647382703:AAE-w7ZRzGoOopTtpiaAF40qlkHapWnMvBU/getUpdates (Caused by NewConnectionError('<telegram.vendor.ptb_urllib3.urllib3.connection.VerifiedHTTPSConnection object at 0x0000000006141A20>: Failed to establish a new connection: [Errno 11004] getaddrinfo failed'))\n",
      "2018-10-29 20:03:52,663 - __main__ - WARNING - Update \"None\" caused error \"urllib3 HTTPError HTTPSConnectionPool(host='api.telegram.org', port=443): Max retries exceeded with url: /bot647382703:AAE-w7ZRzGoOopTtpiaAF40qlkHapWnMvBU/getUpdates (Caused by NewConnectionError('<telegram.vendor.ptb_urllib3.urllib3.connection.VerifiedHTTPSConnection object at 0x0000000006141A20>: Failed to establish a new connection: [Errno 11004] getaddrinfo failed'))\"\n",
      "2018-10-29 20:03:53,663 - telegram.vendor.ptb_urllib3.urllib3.connectionpool - WARNING - Retrying (Retry(total=2, connect=None, read=None, redirect=None)) after connection broken by 'NewConnectionError('<telegram.vendor.ptb_urllib3.urllib3.connection.VerifiedHTTPSConnection object at 0x0000000006129908>: Failed to establish a new connection: [Errno 11004] getaddrinfo failed')': /bot647382703:AAE-w7ZRzGoOopTtpiaAF40qlkHapWnMvBU/getUpdates\n",
      "2018-10-29 20:03:53,665 - telegram.vendor.ptb_urllib3.urllib3.connectionpool - WARNING - Retrying (Retry(total=1, connect=None, read=None, redirect=None)) after connection broken by 'NewConnectionError('<telegram.vendor.ptb_urllib3.urllib3.connection.VerifiedHTTPSConnection object at 0x0000000006129208>: Failed to establish a new connection: [Errno 11004] getaddrinfo failed')': /bot647382703:AAE-w7ZRzGoOopTtpiaAF40qlkHapWnMvBU/getUpdates\n",
      "2018-10-29 20:03:53,666 - telegram.vendor.ptb_urllib3.urllib3.connectionpool - WARNING - Retrying (Retry(total=0, connect=None, read=None, redirect=None)) after connection broken by 'NewConnectionError('<telegram.vendor.ptb_urllib3.urllib3.connection.VerifiedHTTPSConnection object at 0x00000000061297B8>: Failed to establish a new connection: [Errno 11004] getaddrinfo failed')': /bot647382703:AAE-w7ZRzGoOopTtpiaAF40qlkHapWnMvBU/getUpdates\n"
     ]
    },
    {
     "name": "stderr",
     "output_type": "stream",
     "text": [
      "2018-10-29 20:03:53,667 - telegram.ext.updater - ERROR - Error while getting Updates: urllib3 HTTPError HTTPSConnectionPool(host='api.telegram.org', port=443): Max retries exceeded with url: /bot647382703:AAE-w7ZRzGoOopTtpiaAF40qlkHapWnMvBU/getUpdates (Caused by NewConnectionError('<telegram.vendor.ptb_urllib3.urllib3.connection.VerifiedHTTPSConnection object at 0x0000000004D30940>: Failed to establish a new connection: [Errno 11004] getaddrinfo failed'))\n",
      "2018-10-29 20:03:53,667 - __main__ - WARNING - Update \"None\" caused error \"urllib3 HTTPError HTTPSConnectionPool(host='api.telegram.org', port=443): Max retries exceeded with url: /bot647382703:AAE-w7ZRzGoOopTtpiaAF40qlkHapWnMvBU/getUpdates (Caused by NewConnectionError('<telegram.vendor.ptb_urllib3.urllib3.connection.VerifiedHTTPSConnection object at 0x0000000004D30940>: Failed to establish a new connection: [Errno 11004] getaddrinfo failed'))\"\n",
      "2018-10-29 20:03:55,167 - telegram.vendor.ptb_urllib3.urllib3.connectionpool - WARNING - Retrying (Retry(total=2, connect=None, read=None, redirect=None)) after connection broken by 'NewConnectionError('<telegram.vendor.ptb_urllib3.urllib3.connection.VerifiedHTTPSConnection object at 0x000000000611C780>: Failed to establish a new connection: [Errno 11004] getaddrinfo failed')': /bot647382703:AAE-w7ZRzGoOopTtpiaAF40qlkHapWnMvBU/getUpdates\n",
      "2018-10-29 20:03:55,168 - telegram.vendor.ptb_urllib3.urllib3.connectionpool - WARNING - Retrying (Retry(total=1, connect=None, read=None, redirect=None)) after connection broken by 'NewConnectionError('<telegram.vendor.ptb_urllib3.urllib3.connection.VerifiedHTTPSConnection object at 0x000000000611C3C8>: Failed to establish a new connection: [Errno 11004] getaddrinfo failed')': /bot647382703:AAE-w7ZRzGoOopTtpiaAF40qlkHapWnMvBU/getUpdates\n",
      "2018-10-29 20:03:55,169 - telegram.vendor.ptb_urllib3.urllib3.connectionpool - WARNING - Retrying (Retry(total=0, connect=None, read=None, redirect=None)) after connection broken by 'NewConnectionError('<telegram.vendor.ptb_urllib3.urllib3.connection.VerifiedHTTPSConnection object at 0x000000000611CB00>: Failed to establish a new connection: [Errno 11004] getaddrinfo failed')': /bot647382703:AAE-w7ZRzGoOopTtpiaAF40qlkHapWnMvBU/getUpdates\n",
      "2018-10-29 20:03:55,171 - telegram.ext.updater - ERROR - Error while getting Updates: urllib3 HTTPError HTTPSConnectionPool(host='api.telegram.org', port=443): Max retries exceeded with url: /bot647382703:AAE-w7ZRzGoOopTtpiaAF40qlkHapWnMvBU/getUpdates (Caused by NewConnectionError('<telegram.vendor.ptb_urllib3.urllib3.connection.VerifiedHTTPSConnection object at 0x000000000611C470>: Failed to establish a new connection: [Errno 11004] getaddrinfo failed'))\n",
      "2018-10-29 20:03:55,171 - __main__ - WARNING - Update \"None\" caused error \"urllib3 HTTPError HTTPSConnectionPool(host='api.telegram.org', port=443): Max retries exceeded with url: /bot647382703:AAE-w7ZRzGoOopTtpiaAF40qlkHapWnMvBU/getUpdates (Caused by NewConnectionError('<telegram.vendor.ptb_urllib3.urllib3.connection.VerifiedHTTPSConnection object at 0x000000000611C470>: Failed to establish a new connection: [Errno 11004] getaddrinfo failed'))\"\n",
      "2018-10-29 20:03:57,421 - telegram.vendor.ptb_urllib3.urllib3.connectionpool - WARNING - Retrying (Retry(total=2, connect=None, read=None, redirect=None)) after connection broken by 'NewConnectionError('<telegram.vendor.ptb_urllib3.urllib3.connection.VerifiedHTTPSConnection object at 0x000000000611C240>: Failed to establish a new connection: [Errno 11004] getaddrinfo failed')': /bot647382703:AAE-w7ZRzGoOopTtpiaAF40qlkHapWnMvBU/getUpdates\n",
      "2018-10-29 20:03:57,422 - telegram.vendor.ptb_urllib3.urllib3.connectionpool - WARNING - Retrying (Retry(total=1, connect=None, read=None, redirect=None)) after connection broken by 'NewConnectionError('<telegram.vendor.ptb_urllib3.urllib3.connection.VerifiedHTTPSConnection object at 0x000000000611C2E8>: Failed to establish a new connection: [Errno 11004] getaddrinfo failed')': /bot647382703:AAE-w7ZRzGoOopTtpiaAF40qlkHapWnMvBU/getUpdates\n",
      "2018-10-29 20:03:57,424 - telegram.vendor.ptb_urllib3.urllib3.connectionpool - WARNING - Retrying (Retry(total=0, connect=None, read=None, redirect=None)) after connection broken by 'NewConnectionError('<telegram.vendor.ptb_urllib3.urllib3.connection.VerifiedHTTPSConnection object at 0x000000000611CE48>: Failed to establish a new connection: [Errno 11004] getaddrinfo failed')': /bot647382703:AAE-w7ZRzGoOopTtpiaAF40qlkHapWnMvBU/getUpdates\n",
      "2018-10-29 20:03:57,425 - telegram.ext.updater - ERROR - Error while getting Updates: urllib3 HTTPError HTTPSConnectionPool(host='api.telegram.org', port=443): Max retries exceeded with url: /bot647382703:AAE-w7ZRzGoOopTtpiaAF40qlkHapWnMvBU/getUpdates (Caused by NewConnectionError('<telegram.vendor.ptb_urllib3.urllib3.connection.VerifiedHTTPSConnection object at 0x000000000611C208>: Failed to establish a new connection: [Errno 11004] getaddrinfo failed'))\n",
      "2018-10-29 20:03:57,425 - __main__ - WARNING - Update \"None\" caused error \"urllib3 HTTPError HTTPSConnectionPool(host='api.telegram.org', port=443): Max retries exceeded with url: /bot647382703:AAE-w7ZRzGoOopTtpiaAF40qlkHapWnMvBU/getUpdates (Caused by NewConnectionError('<telegram.vendor.ptb_urllib3.urllib3.connection.VerifiedHTTPSConnection object at 0x000000000611C208>: Failed to establish a new connection: [Errno 11004] getaddrinfo failed'))\"\n",
      "2018-10-29 22:04:07,716 - telegram.vendor.ptb_urllib3.urllib3.connectionpool - WARNING - Retrying (Retry(total=2, connect=None, read=None, redirect=None)) after connection broken by 'NewConnectionError('<telegram.vendor.ptb_urllib3.urllib3.connection.VerifiedHTTPSConnection object at 0x00000000061292B0>: Failed to establish a new connection: [Errno 11004] getaddrinfo failed')': /bot647382703:AAE-w7ZRzGoOopTtpiaAF40qlkHapWnMvBU/getUpdates\n",
      "2018-10-29 22:04:07,719 - telegram.vendor.ptb_urllib3.urllib3.connectionpool - WARNING - Retrying (Retry(total=1, connect=None, read=None, redirect=None)) after connection broken by 'NewConnectionError('<telegram.vendor.ptb_urllib3.urllib3.connection.VerifiedHTTPSConnection object at 0x00000000061294A8>: Failed to establish a new connection: [Errno 11004] getaddrinfo failed')': /bot647382703:AAE-w7ZRzGoOopTtpiaAF40qlkHapWnMvBU/getUpdates\n",
      "2018-10-29 22:04:07,720 - telegram.vendor.ptb_urllib3.urllib3.connectionpool - WARNING - Retrying (Retry(total=0, connect=None, read=None, redirect=None)) after connection broken by 'NewConnectionError('<telegram.vendor.ptb_urllib3.urllib3.connection.VerifiedHTTPSConnection object at 0x0000000006129160>: Failed to establish a new connection: [Errno 11004] getaddrinfo failed')': /bot647382703:AAE-w7ZRzGoOopTtpiaAF40qlkHapWnMvBU/getUpdates\n",
      "2018-10-29 22:04:07,721 - telegram.ext.updater - ERROR - Error while getting Updates: urllib3 HTTPError HTTPSConnectionPool(host='api.telegram.org', port=443): Max retries exceeded with url: /bot647382703:AAE-w7ZRzGoOopTtpiaAF40qlkHapWnMvBU/getUpdates (Caused by NewConnectionError('<telegram.vendor.ptb_urllib3.urllib3.connection.VerifiedHTTPSConnection object at 0x0000000006129F28>: Failed to establish a new connection: [Errno 11004] getaddrinfo failed'))\n",
      "2018-10-29 22:04:07,722 - __main__ - WARNING - Update \"None\" caused error \"urllib3 HTTPError HTTPSConnectionPool(host='api.telegram.org', port=443): Max retries exceeded with url: /bot647382703:AAE-w7ZRzGoOopTtpiaAF40qlkHapWnMvBU/getUpdates (Caused by NewConnectionError('<telegram.vendor.ptb_urllib3.urllib3.connection.VerifiedHTTPSConnection object at 0x0000000006129F28>: Failed to establish a new connection: [Errno 11004] getaddrinfo failed'))\"\n",
      "2018-10-29 23:39:42,588 - telegram.vendor.ptb_urllib3.urllib3.connectionpool - WARNING - Retrying (Retry(total=2, connect=None, read=None, redirect=None)) after connection broken by 'NewConnectionError('<telegram.vendor.ptb_urllib3.urllib3.connection.VerifiedHTTPSConnection object at 0x000000000613AA58>: Failed to establish a new connection: [Errno 11004] getaddrinfo failed')': /bot647382703:AAE-w7ZRzGoOopTtpiaAF40qlkHapWnMvBU/getUpdates\n",
      "2018-10-29 23:39:42,590 - telegram.vendor.ptb_urllib3.urllib3.connectionpool - WARNING - Retrying (Retry(total=1, connect=None, read=None, redirect=None)) after connection broken by 'NewConnectionError('<telegram.vendor.ptb_urllib3.urllib3.connection.VerifiedHTTPSConnection object at 0x000000000613A588>: Failed to establish a new connection: [Errno 11004] getaddrinfo failed')': /bot647382703:AAE-w7ZRzGoOopTtpiaAF40qlkHapWnMvBU/getUpdates\n"
     ]
    },
    {
     "name": "stderr",
     "output_type": "stream",
     "text": [
      "2018-10-29 23:39:42,592 - telegram.vendor.ptb_urllib3.urllib3.connectionpool - WARNING - Retrying (Retry(total=0, connect=None, read=None, redirect=None)) after connection broken by 'NewConnectionError('<telegram.vendor.ptb_urllib3.urllib3.connection.VerifiedHTTPSConnection object at 0x000000000613AC50>: Failed to establish a new connection: [Errno 11004] getaddrinfo failed')': /bot647382703:AAE-w7ZRzGoOopTtpiaAF40qlkHapWnMvBU/getUpdates\n",
      "2018-10-29 23:39:42,596 - telegram.ext.updater - ERROR - Error while getting Updates: urllib3 HTTPError HTTPSConnectionPool(host='api.telegram.org', port=443): Max retries exceeded with url: /bot647382703:AAE-w7ZRzGoOopTtpiaAF40qlkHapWnMvBU/getUpdates (Caused by NewConnectionError('<telegram.vendor.ptb_urllib3.urllib3.connection.VerifiedHTTPSConnection object at 0x000000000613A320>: Failed to establish a new connection: [Errno 11004] getaddrinfo failed'))\n",
      "2018-10-29 23:39:42,599 - __main__ - WARNING - Update \"None\" caused error \"urllib3 HTTPError HTTPSConnectionPool(host='api.telegram.org', port=443): Max retries exceeded with url: /bot647382703:AAE-w7ZRzGoOopTtpiaAF40qlkHapWnMvBU/getUpdates (Caused by NewConnectionError('<telegram.vendor.ptb_urllib3.urllib3.connection.VerifiedHTTPSConnection object at 0x000000000613A320>: Failed to establish a new connection: [Errno 11004] getaddrinfo failed'))\"\n",
      "2018-10-29 23:39:44,099 - telegram.vendor.ptb_urllib3.urllib3.connectionpool - WARNING - Retrying (Retry(total=2, connect=None, read=None, redirect=None)) after connection broken by 'NewConnectionError('<telegram.vendor.ptb_urllib3.urllib3.connection.VerifiedHTTPSConnection object at 0x000000000613A4A8>: Failed to establish a new connection: [Errno 11004] getaddrinfo failed')': /bot647382703:AAE-w7ZRzGoOopTtpiaAF40qlkHapWnMvBU/getUpdates\n",
      "2018-10-29 23:39:44,100 - telegram.vendor.ptb_urllib3.urllib3.connectionpool - WARNING - Retrying (Retry(total=1, connect=None, read=None, redirect=None)) after connection broken by 'NewConnectionError('<telegram.vendor.ptb_urllib3.urllib3.connection.VerifiedHTTPSConnection object at 0x000000000613A9E8>: Failed to establish a new connection: [Errno 11004] getaddrinfo failed')': /bot647382703:AAE-w7ZRzGoOopTtpiaAF40qlkHapWnMvBU/getUpdates\n",
      "2018-10-29 23:39:44,101 - telegram.vendor.ptb_urllib3.urllib3.connectionpool - WARNING - Retrying (Retry(total=0, connect=None, read=None, redirect=None)) after connection broken by 'NewConnectionError('<telegram.vendor.ptb_urllib3.urllib3.connection.VerifiedHTTPSConnection object at 0x000000000613A0F0>: Failed to establish a new connection: [Errno 11004] getaddrinfo failed')': /bot647382703:AAE-w7ZRzGoOopTtpiaAF40qlkHapWnMvBU/getUpdates\n",
      "2018-10-29 23:39:44,102 - telegram.ext.updater - ERROR - Error while getting Updates: urllib3 HTTPError HTTPSConnectionPool(host='api.telegram.org', port=443): Max retries exceeded with url: /bot647382703:AAE-w7ZRzGoOopTtpiaAF40qlkHapWnMvBU/getUpdates (Caused by NewConnectionError('<telegram.vendor.ptb_urllib3.urllib3.connection.VerifiedHTTPSConnection object at 0x000000000613A940>: Failed to establish a new connection: [Errno 11004] getaddrinfo failed'))\n",
      "2018-10-29 23:39:44,103 - __main__ - WARNING - Update \"None\" caused error \"urllib3 HTTPError HTTPSConnectionPool(host='api.telegram.org', port=443): Max retries exceeded with url: /bot647382703:AAE-w7ZRzGoOopTtpiaAF40qlkHapWnMvBU/getUpdates (Caused by NewConnectionError('<telegram.vendor.ptb_urllib3.urllib3.connection.VerifiedHTTPSConnection object at 0x000000000613A940>: Failed to establish a new connection: [Errno 11004] getaddrinfo failed'))\"\n",
      "2018-10-29 23:39:46,353 - telegram.vendor.ptb_urllib3.urllib3.connectionpool - WARNING - Retrying (Retry(total=2, connect=None, read=None, redirect=None)) after connection broken by 'NewConnectionError('<telegram.vendor.ptb_urllib3.urllib3.connection.VerifiedHTTPSConnection object at 0x000000000613A5F8>: Failed to establish a new connection: [Errno 11004] getaddrinfo failed')': /bot647382703:AAE-w7ZRzGoOopTtpiaAF40qlkHapWnMvBU/getUpdates\n",
      "2018-10-29 23:39:46,355 - telegram.vendor.ptb_urllib3.urllib3.connectionpool - WARNING - Retrying (Retry(total=1, connect=None, read=None, redirect=None)) after connection broken by 'NewConnectionError('<telegram.vendor.ptb_urllib3.urllib3.connection.VerifiedHTTPSConnection object at 0x000000000613A470>: Failed to establish a new connection: [Errno 11004] getaddrinfo failed')': /bot647382703:AAE-w7ZRzGoOopTtpiaAF40qlkHapWnMvBU/getUpdates\n",
      "2018-10-29 23:39:46,356 - telegram.vendor.ptb_urllib3.urllib3.connectionpool - WARNING - Retrying (Retry(total=0, connect=None, read=None, redirect=None)) after connection broken by 'NewConnectionError('<telegram.vendor.ptb_urllib3.urllib3.connection.VerifiedHTTPSConnection object at 0x000000000613A710>: Failed to establish a new connection: [Errno 11004] getaddrinfo failed')': /bot647382703:AAE-w7ZRzGoOopTtpiaAF40qlkHapWnMvBU/getUpdates\n",
      "2018-10-29 23:39:46,357 - telegram.ext.updater - ERROR - Error while getting Updates: urllib3 HTTPError HTTPSConnectionPool(host='api.telegram.org', port=443): Max retries exceeded with url: /bot647382703:AAE-w7ZRzGoOopTtpiaAF40qlkHapWnMvBU/getUpdates (Caused by NewConnectionError('<telegram.vendor.ptb_urllib3.urllib3.connection.VerifiedHTTPSConnection object at 0x0000000006141AC8>: Failed to establish a new connection: [Errno 11004] getaddrinfo failed'))\n",
      "2018-10-29 23:39:46,358 - __main__ - WARNING - Update \"None\" caused error \"urllib3 HTTPError HTTPSConnectionPool(host='api.telegram.org', port=443): Max retries exceeded with url: /bot647382703:AAE-w7ZRzGoOopTtpiaAF40qlkHapWnMvBU/getUpdates (Caused by NewConnectionError('<telegram.vendor.ptb_urllib3.urllib3.connection.VerifiedHTTPSConnection object at 0x0000000006141AC8>: Failed to establish a new connection: [Errno 11004] getaddrinfo failed'))\"\n",
      "2018-10-30 08:55:04,585 - telegram.vendor.ptb_urllib3.urllib3.connectionpool - WARNING - Retrying (Retry(total=2, connect=None, read=None, redirect=None)) after connection broken by 'NewConnectionError('<telegram.vendor.ptb_urllib3.urllib3.connection.VerifiedHTTPSConnection object at 0x000000000613ADA0>: Failed to establish a new connection: [Errno 11004] getaddrinfo failed')': /bot647382703:AAE-w7ZRzGoOopTtpiaAF40qlkHapWnMvBU/getUpdates\n",
      "2018-10-30 08:55:04,643 - telegram.vendor.ptb_urllib3.urllib3.connectionpool - WARNING - Retrying (Retry(total=1, connect=None, read=None, redirect=None)) after connection broken by 'NewConnectionError('<telegram.vendor.ptb_urllib3.urllib3.connection.VerifiedHTTPSConnection object at 0x000000000613AA90>: Failed to establish a new connection: [Errno 11004] getaddrinfo failed')': /bot647382703:AAE-w7ZRzGoOopTtpiaAF40qlkHapWnMvBU/getUpdates\n",
      "2018-10-30 08:55:04,678 - telegram.vendor.ptb_urllib3.urllib3.connectionpool - WARNING - Retrying (Retry(total=0, connect=None, read=None, redirect=None)) after connection broken by 'NewConnectionError('<telegram.vendor.ptb_urllib3.urllib3.connection.VerifiedHTTPSConnection object at 0x000000000613A588>: Failed to establish a new connection: [Errno 11004] getaddrinfo failed')': /bot647382703:AAE-w7ZRzGoOopTtpiaAF40qlkHapWnMvBU/getUpdates\n",
      "2018-10-30 08:55:10,248 - telegram.ext.updater - ERROR - Error while getting Updates: urllib3 HTTPError HTTPSConnectionPool(host='api.telegram.org', port=443): Max retries exceeded with url: /bot647382703:AAE-w7ZRzGoOopTtpiaAF40qlkHapWnMvBU/getUpdates (Caused by NewConnectionError('<telegram.vendor.ptb_urllib3.urllib3.connection.VerifiedHTTPSConnection object at 0x000000000613A668>: Failed to establish a new connection: [Errno 11004] getaddrinfo failed'))\n",
      "2018-10-30 08:55:10,250 - __main__ - WARNING - Update \"None\" caused error \"urllib3 HTTPError HTTPSConnectionPool(host='api.telegram.org', port=443): Max retries exceeded with url: /bot647382703:AAE-w7ZRzGoOopTtpiaAF40qlkHapWnMvBU/getUpdates (Caused by NewConnectionError('<telegram.vendor.ptb_urllib3.urllib3.connection.VerifiedHTTPSConnection object at 0x000000000613A668>: Failed to establish a new connection: [Errno 11004] getaddrinfo failed'))\"\n",
      "2018-10-30 08:55:11,275 - telegram.vendor.ptb_urllib3.urllib3.connectionpool - WARNING - Retrying (Retry(total=2, connect=None, read=None, redirect=None)) after connection broken by 'NewConnectionError('<telegram.vendor.ptb_urllib3.urllib3.connection.VerifiedHTTPSConnection object at 0x000000000613AC18>: Failed to establish a new connection: [Errno 11004] getaddrinfo failed')': /bot647382703:AAE-w7ZRzGoOopTtpiaAF40qlkHapWnMvBU/getUpdates\n"
     ]
    },
    {
     "name": "stderr",
     "output_type": "stream",
     "text": [
      "2018-10-30 08:55:11,277 - telegram.vendor.ptb_urllib3.urllib3.connectionpool - WARNING - Retrying (Retry(total=1, connect=None, read=None, redirect=None)) after connection broken by 'NewConnectionError('<telegram.vendor.ptb_urllib3.urllib3.connection.VerifiedHTTPSConnection object at 0x000000000616AC18>: Failed to establish a new connection: [Errno 11004] getaddrinfo failed')': /bot647382703:AAE-w7ZRzGoOopTtpiaAF40qlkHapWnMvBU/getUpdates\n",
      "2018-10-30 08:55:12,236 - telegram.vendor.ptb_urllib3.urllib3.connectionpool - WARNING - Retrying (Retry(total=0, connect=None, read=None, redirect=None)) after connection broken by 'NewConnectionError('<telegram.vendor.ptb_urllib3.urllib3.connection.VerifiedHTTPSConnection object at 0x000000000616A828>: Failed to establish a new connection: [Errno 11004] getaddrinfo failed')': /bot647382703:AAE-w7ZRzGoOopTtpiaAF40qlkHapWnMvBU/getUpdates\n",
      "2018-10-30 08:55:12,265 - telegram.ext.updater - ERROR - Error while getting Updates: urllib3 HTTPError HTTPSConnectionPool(host='api.telegram.org', port=443): Max retries exceeded with url: /bot647382703:AAE-w7ZRzGoOopTtpiaAF40qlkHapWnMvBU/getUpdates (Caused by NewConnectionError('<telegram.vendor.ptb_urllib3.urllib3.connection.VerifiedHTTPSConnection object at 0x000000000616A6D8>: Failed to establish a new connection: [Errno 11004] getaddrinfo failed'))\n",
      "2018-10-30 08:55:12,267 - __main__ - WARNING - Update \"None\" caused error \"urllib3 HTTPError HTTPSConnectionPool(host='api.telegram.org', port=443): Max retries exceeded with url: /bot647382703:AAE-w7ZRzGoOopTtpiaAF40qlkHapWnMvBU/getUpdates (Caused by NewConnectionError('<telegram.vendor.ptb_urllib3.urllib3.connection.VerifiedHTTPSConnection object at 0x000000000616A6D8>: Failed to establish a new connection: [Errno 11004] getaddrinfo failed'))\"\n",
      "2018-10-30 08:55:13,767 - telegram.vendor.ptb_urllib3.urllib3.connectionpool - WARNING - Retrying (Retry(total=2, connect=None, read=None, redirect=None)) after connection broken by 'NewConnectionError('<telegram.vendor.ptb_urllib3.urllib3.connection.VerifiedHTTPSConnection object at 0x000000000613A9B0>: Failed to establish a new connection: [Errno 11004] getaddrinfo failed')': /bot647382703:AAE-w7ZRzGoOopTtpiaAF40qlkHapWnMvBU/getUpdates\n",
      "2018-10-30 08:55:13,768 - telegram.vendor.ptb_urllib3.urllib3.connectionpool - WARNING - Retrying (Retry(total=1, connect=None, read=None, redirect=None)) after connection broken by 'NewConnectionError('<telegram.vendor.ptb_urllib3.urllib3.connection.VerifiedHTTPSConnection object at 0x00000000060E4B70>: Failed to establish a new connection: [Errno 11004] getaddrinfo failed')': /bot647382703:AAE-w7ZRzGoOopTtpiaAF40qlkHapWnMvBU/getUpdates\n",
      "2018-10-30 08:55:13,769 - telegram.vendor.ptb_urllib3.urllib3.connectionpool - WARNING - Retrying (Retry(total=0, connect=None, read=None, redirect=None)) after connection broken by 'NewConnectionError('<telegram.vendor.ptb_urllib3.urllib3.connection.VerifiedHTTPSConnection object at 0x000000000311B7B8>: Failed to establish a new connection: [Errno 11004] getaddrinfo failed')': /bot647382703:AAE-w7ZRzGoOopTtpiaAF40qlkHapWnMvBU/getUpdates\n",
      "2018-10-30 08:55:13,770 - telegram.ext.updater - ERROR - Error while getting Updates: urllib3 HTTPError HTTPSConnectionPool(host='api.telegram.org', port=443): Max retries exceeded with url: /bot647382703:AAE-w7ZRzGoOopTtpiaAF40qlkHapWnMvBU/getUpdates (Caused by NewConnectionError('<telegram.vendor.ptb_urllib3.urllib3.connection.VerifiedHTTPSConnection object at 0x00000000060F6EF0>: Failed to establish a new connection: [Errno 11004] getaddrinfo failed'))\n",
      "2018-10-30 08:55:13,770 - __main__ - WARNING - Update \"None\" caused error \"urllib3 HTTPError HTTPSConnectionPool(host='api.telegram.org', port=443): Max retries exceeded with url: /bot647382703:AAE-w7ZRzGoOopTtpiaAF40qlkHapWnMvBU/getUpdates (Caused by NewConnectionError('<telegram.vendor.ptb_urllib3.urllib3.connection.VerifiedHTTPSConnection object at 0x00000000060F6EF0>: Failed to establish a new connection: [Errno 11004] getaddrinfo failed'))\"\n",
      "2018-10-30 12:18:53,535 - telegram.vendor.ptb_urllib3.urllib3.connectionpool - WARNING - Retrying (Retry(total=2, connect=None, read=None, redirect=None)) after connection broken by 'NewConnectionError('<telegram.vendor.ptb_urllib3.urllib3.connection.VerifiedHTTPSConnection object at 0x000000000613AA90>: Failed to establish a new connection: [Errno 11004] getaddrinfo failed')': /bot647382703:AAE-w7ZRzGoOopTtpiaAF40qlkHapWnMvBU/getUpdates\n",
      "2018-10-30 12:18:53,539 - telegram.vendor.ptb_urllib3.urllib3.connectionpool - WARNING - Retrying (Retry(total=1, connect=None, read=None, redirect=None)) after connection broken by 'NewConnectionError('<telegram.vendor.ptb_urllib3.urllib3.connection.VerifiedHTTPSConnection object at 0x000000000613A2B0>: Failed to establish a new connection: [Errno 11004] getaddrinfo failed')': /bot647382703:AAE-w7ZRzGoOopTtpiaAF40qlkHapWnMvBU/getUpdates\n",
      "2018-10-30 12:18:53,540 - telegram.vendor.ptb_urllib3.urllib3.connectionpool - WARNING - Retrying (Retry(total=0, connect=None, read=None, redirect=None)) after connection broken by 'NewConnectionError('<telegram.vendor.ptb_urllib3.urllib3.connection.VerifiedHTTPSConnection object at 0x000000000613A048>: Failed to establish a new connection: [Errno 11004] getaddrinfo failed')': /bot647382703:AAE-w7ZRzGoOopTtpiaAF40qlkHapWnMvBU/getUpdates\n",
      "2018-10-30 12:18:53,555 - telegram.ext.updater - ERROR - Error while getting Updates: urllib3 HTTPError HTTPSConnectionPool(host='api.telegram.org', port=443): Max retries exceeded with url: /bot647382703:AAE-w7ZRzGoOopTtpiaAF40qlkHapWnMvBU/getUpdates (Caused by NewConnectionError('<telegram.vendor.ptb_urllib3.urllib3.connection.VerifiedHTTPSConnection object at 0x000000000616A8D0>: Failed to establish a new connection: [Errno 11004] getaddrinfo failed'))\n",
      "2018-10-30 12:18:53,557 - __main__ - WARNING - Update \"None\" caused error \"urllib3 HTTPError HTTPSConnectionPool(host='api.telegram.org', port=443): Max retries exceeded with url: /bot647382703:AAE-w7ZRzGoOopTtpiaAF40qlkHapWnMvBU/getUpdates (Caused by NewConnectionError('<telegram.vendor.ptb_urllib3.urllib3.connection.VerifiedHTTPSConnection object at 0x000000000616A8D0>: Failed to establish a new connection: [Errno 11004] getaddrinfo failed'))\"\n",
      "2018-10-30 12:18:54,557 - telegram.vendor.ptb_urllib3.urllib3.connectionpool - WARNING - Retrying (Retry(total=2, connect=None, read=None, redirect=None)) after connection broken by 'NewConnectionError('<telegram.vendor.ptb_urllib3.urllib3.connection.VerifiedHTTPSConnection object at 0x000000000613A8D0>: Failed to establish a new connection: [Errno 11004] getaddrinfo failed')': /bot647382703:AAE-w7ZRzGoOopTtpiaAF40qlkHapWnMvBU/getUpdates\n",
      "2018-10-30 12:18:54,559 - telegram.vendor.ptb_urllib3.urllib3.connectionpool - WARNING - Retrying (Retry(total=1, connect=None, read=None, redirect=None)) after connection broken by 'NewConnectionError('<telegram.vendor.ptb_urllib3.urllib3.connection.VerifiedHTTPSConnection object at 0x0000000006179E10>: Failed to establish a new connection: [Errno 11004] getaddrinfo failed')': /bot647382703:AAE-w7ZRzGoOopTtpiaAF40qlkHapWnMvBU/getUpdates\n",
      "2018-10-30 12:18:54,561 - telegram.vendor.ptb_urllib3.urllib3.connectionpool - WARNING - Retrying (Retry(total=0, connect=None, read=None, redirect=None)) after connection broken by 'NewConnectionError('<telegram.vendor.ptb_urllib3.urllib3.connection.VerifiedHTTPSConnection object at 0x0000000006179F98>: Failed to establish a new connection: [Errno 11004] getaddrinfo failed')': /bot647382703:AAE-w7ZRzGoOopTtpiaAF40qlkHapWnMvBU/getUpdates\n",
      "2018-10-30 12:18:54,562 - telegram.ext.updater - ERROR - Error while getting Updates: urllib3 HTTPError HTTPSConnectionPool(host='api.telegram.org', port=443): Max retries exceeded with url: /bot647382703:AAE-w7ZRzGoOopTtpiaAF40qlkHapWnMvBU/getUpdates (Caused by NewConnectionError('<telegram.vendor.ptb_urllib3.urllib3.connection.VerifiedHTTPSConnection object at 0x00000000061797B8>: Failed to establish a new connection: [Errno 11004] getaddrinfo failed'))\n",
      "2018-10-30 12:18:54,562 - __main__ - WARNING - Update \"None\" caused error \"urllib3 HTTPError HTTPSConnectionPool(host='api.telegram.org', port=443): Max retries exceeded with url: /bot647382703:AAE-w7ZRzGoOopTtpiaAF40qlkHapWnMvBU/getUpdates (Caused by NewConnectionError('<telegram.vendor.ptb_urllib3.urllib3.connection.VerifiedHTTPSConnection object at 0x00000000061797B8>: Failed to establish a new connection: [Errno 11004] getaddrinfo failed'))\"\n"
     ]
    },
    {
     "name": "stderr",
     "output_type": "stream",
     "text": [
      "2018-10-30 12:18:56,062 - telegram.vendor.ptb_urllib3.urllib3.connectionpool - WARNING - Retrying (Retry(total=2, connect=None, read=None, redirect=None)) after connection broken by 'NewConnectionError('<telegram.vendor.ptb_urllib3.urllib3.connection.VerifiedHTTPSConnection object at 0x000000000613AC50>: Failed to establish a new connection: [Errno 11004] getaddrinfo failed')': /bot647382703:AAE-w7ZRzGoOopTtpiaAF40qlkHapWnMvBU/getUpdates\n",
      "2018-10-30 12:18:56,064 - telegram.vendor.ptb_urllib3.urllib3.connectionpool - WARNING - Retrying (Retry(total=1, connect=None, read=None, redirect=None)) after connection broken by 'NewConnectionError('<telegram.vendor.ptb_urllib3.urllib3.connection.VerifiedHTTPSConnection object at 0x0000000006129208>: Failed to establish a new connection: [Errno 11004] getaddrinfo failed')': /bot647382703:AAE-w7ZRzGoOopTtpiaAF40qlkHapWnMvBU/getUpdates\n",
      "2018-10-30 12:18:56,065 - telegram.vendor.ptb_urllib3.urllib3.connectionpool - WARNING - Retrying (Retry(total=0, connect=None, read=None, redirect=None)) after connection broken by 'NewConnectionError('<telegram.vendor.ptb_urllib3.urllib3.connection.VerifiedHTTPSConnection object at 0x0000000006129A90>: Failed to establish a new connection: [Errno 11004] getaddrinfo failed')': /bot647382703:AAE-w7ZRzGoOopTtpiaAF40qlkHapWnMvBU/getUpdates\n",
      "2018-10-30 12:18:56,066 - telegram.ext.updater - ERROR - Error while getting Updates: urllib3 HTTPError HTTPSConnectionPool(host='api.telegram.org', port=443): Max retries exceeded with url: /bot647382703:AAE-w7ZRzGoOopTtpiaAF40qlkHapWnMvBU/getUpdates (Caused by NewConnectionError('<telegram.vendor.ptb_urllib3.urllib3.connection.VerifiedHTTPSConnection object at 0x0000000006129CC0>: Failed to establish a new connection: [Errno 11004] getaddrinfo failed'))\n",
      "2018-10-30 12:18:56,067 - __main__ - WARNING - Update \"None\" caused error \"urllib3 HTTPError HTTPSConnectionPool(host='api.telegram.org', port=443): Max retries exceeded with url: /bot647382703:AAE-w7ZRzGoOopTtpiaAF40qlkHapWnMvBU/getUpdates (Caused by NewConnectionError('<telegram.vendor.ptb_urllib3.urllib3.connection.VerifiedHTTPSConnection object at 0x0000000006129CC0>: Failed to establish a new connection: [Errno 11004] getaddrinfo failed'))\"\n",
      "2018-10-30 14:45:34,549 - telegram.vendor.ptb_urllib3.urllib3.connectionpool - WARNING - Retrying (Retry(total=2, connect=None, read=None, redirect=None)) after connection broken by 'NewConnectionError('<telegram.vendor.ptb_urllib3.urllib3.connection.VerifiedHTTPSConnection object at 0x0000000003EC85C0>: Failed to establish a new connection: [Errno 11004] getaddrinfo failed')': /bot647382703:AAE-w7ZRzGoOopTtpiaAF40qlkHapWnMvBU/getUpdates\n",
      "2018-10-30 16:52:19,527 - telegram.vendor.ptb_urllib3.urllib3.connectionpool - WARNING - Retrying (Retry(total=2, connect=None, read=None, redirect=None)) after connection broken by 'NewConnectionError('<telegram.vendor.ptb_urllib3.urllib3.connection.VerifiedHTTPSConnection object at 0x0000000003EC86A0>: Failed to establish a new connection: [Errno 11004] getaddrinfo failed')': /bot647382703:AAE-w7ZRzGoOopTtpiaAF40qlkHapWnMvBU/getUpdates\n",
      "2018-10-30 16:52:19,552 - telegram.vendor.ptb_urllib3.urllib3.connectionpool - WARNING - Retrying (Retry(total=1, connect=None, read=None, redirect=None)) after connection broken by 'NewConnectionError('<telegram.vendor.ptb_urllib3.urllib3.connection.VerifiedHTTPSConnection object at 0x0000000003EC8358>: Failed to establish a new connection: [Errno 11004] getaddrinfo failed')': /bot647382703:AAE-w7ZRzGoOopTtpiaAF40qlkHapWnMvBU/getUpdates\n",
      "2018-10-30 16:52:19,554 - telegram.vendor.ptb_urllib3.urllib3.connectionpool - WARNING - Retrying (Retry(total=0, connect=None, read=None, redirect=None)) after connection broken by 'NewConnectionError('<telegram.vendor.ptb_urllib3.urllib3.connection.VerifiedHTTPSConnection object at 0x0000000003EC8DD8>: Failed to establish a new connection: [Errno 11004] getaddrinfo failed')': /bot647382703:AAE-w7ZRzGoOopTtpiaAF40qlkHapWnMvBU/getUpdates\n",
      "2018-10-30 19:22:35,702 - telegram.vendor.ptb_urllib3.urllib3.connectionpool - WARNING - Retrying (Retry(total=2, connect=None, read=None, redirect=None)) after connection broken by 'ConnectTimeoutError(<telegram.vendor.ptb_urllib3.urllib3.connectionpool.HTTPSConnectionPool object at 0x00000000060E4A58>, 'Connect timed out. (connect timeout=5.0)')': /bot647382703:AAE-w7ZRzGoOopTtpiaAF40qlkHapWnMvBU/getUpdates\n",
      "2018-10-30 19:22:40,705 - telegram.vendor.ptb_urllib3.urllib3.connectionpool - WARNING - Retrying (Retry(total=1, connect=None, read=None, redirect=None)) after connection broken by 'ConnectTimeoutError(<telegram.vendor.ptb_urllib3.urllib3.connection.VerifiedHTTPSConnection object at 0x0000000003EC86A0>, 'Connection to api.telegram.org timed out. (connect timeout=5.0)')': /bot647382703:AAE-w7ZRzGoOopTtpiaAF40qlkHapWnMvBU/getUpdates\n",
      "2018-10-30 23:33:48,558 - telegram.vendor.ptb_urllib3.urllib3.connectionpool - WARNING - Retrying (Retry(total=2, connect=None, read=None, redirect=None)) after connection broken by 'NewConnectionError('<telegram.vendor.ptb_urllib3.urllib3.connection.VerifiedHTTPSConnection object at 0x0000000003ED5C88>: Failed to establish a new connection: [Errno 11004] getaddrinfo failed')': /bot647382703:AAE-w7ZRzGoOopTtpiaAF40qlkHapWnMvBU/getUpdates\n",
      "2018-10-30 23:33:48,565 - telegram.vendor.ptb_urllib3.urllib3.connectionpool - WARNING - Retrying (Retry(total=1, connect=None, read=None, redirect=None)) after connection broken by 'NewConnectionError('<telegram.vendor.ptb_urllib3.urllib3.connection.VerifiedHTTPSConnection object at 0x000000000614EA20>: Failed to establish a new connection: [Errno 11004] getaddrinfo failed')': /bot647382703:AAE-w7ZRzGoOopTtpiaAF40qlkHapWnMvBU/getUpdates\n",
      "2018-10-30 23:33:48,569 - telegram.vendor.ptb_urllib3.urllib3.connectionpool - WARNING - Retrying (Retry(total=0, connect=None, read=None, redirect=None)) after connection broken by 'NewConnectionError('<telegram.vendor.ptb_urllib3.urllib3.connection.VerifiedHTTPSConnection object at 0x000000000611C630>: Failed to establish a new connection: [Errno 11004] getaddrinfo failed')': /bot647382703:AAE-w7ZRzGoOopTtpiaAF40qlkHapWnMvBU/getUpdates\n",
      "2018-10-30 23:33:48,571 - telegram.ext.updater - ERROR - Error while getting Updates: urllib3 HTTPError HTTPSConnectionPool(host='api.telegram.org', port=443): Max retries exceeded with url: /bot647382703:AAE-w7ZRzGoOopTtpiaAF40qlkHapWnMvBU/getUpdates (Caused by NewConnectionError('<telegram.vendor.ptb_urllib3.urllib3.connection.VerifiedHTTPSConnection object at 0x000000000611CC50>: Failed to establish a new connection: [Errno 11004] getaddrinfo failed'))\n",
      "2018-10-30 23:33:48,574 - __main__ - WARNING - Update \"None\" caused error \"urllib3 HTTPError HTTPSConnectionPool(host='api.telegram.org', port=443): Max retries exceeded with url: /bot647382703:AAE-w7ZRzGoOopTtpiaAF40qlkHapWnMvBU/getUpdates (Caused by NewConnectionError('<telegram.vendor.ptb_urllib3.urllib3.connection.VerifiedHTTPSConnection object at 0x000000000611CC50>: Failed to establish a new connection: [Errno 11004] getaddrinfo failed'))\"\n",
      "2018-10-30 23:33:49,572 - telegram.vendor.ptb_urllib3.urllib3.connectionpool - WARNING - Retrying (Retry(total=2, connect=None, read=None, redirect=None)) after connection broken by 'NewConnectionError('<telegram.vendor.ptb_urllib3.urllib3.connection.VerifiedHTTPSConnection object at 0x00000000061797B8>: Failed to establish a new connection: [Errno 11004] getaddrinfo failed')': /bot647382703:AAE-w7ZRzGoOopTtpiaAF40qlkHapWnMvBU/getUpdates\n",
      "2018-10-30 23:33:49,574 - telegram.vendor.ptb_urllib3.urllib3.connectionpool - WARNING - Retrying (Retry(total=1, connect=None, read=None, redirect=None)) after connection broken by 'NewConnectionError('<telegram.vendor.ptb_urllib3.urllib3.connection.VerifiedHTTPSConnection object at 0x0000000006179C88>: Failed to establish a new connection: [Errno 11004] getaddrinfo failed')': /bot647382703:AAE-w7ZRzGoOopTtpiaAF40qlkHapWnMvBU/getUpdates\n",
      "2018-10-31 08:44:59,565 - telegram.vendor.ptb_urllib3.urllib3.connectionpool - WARNING - Retrying (Retry(total=2, connect=None, read=None, redirect=None)) after connection broken by 'NewConnectionError('<telegram.vendor.ptb_urllib3.urllib3.connection.VerifiedHTTPSConnection object at 0x000000000616AB00>: Failed to establish a new connection: [Errno 11004] getaddrinfo failed')': /bot647382703:AAE-w7ZRzGoOopTtpiaAF40qlkHapWnMvBU/getUpdates\n"
     ]
    },
    {
     "name": "stderr",
     "output_type": "stream",
     "text": [
      "2018-10-31 08:44:59,602 - telegram.vendor.ptb_urllib3.urllib3.connectionpool - WARNING - Retrying (Retry(total=1, connect=None, read=None, redirect=None)) after connection broken by 'NewConnectionError('<telegram.vendor.ptb_urllib3.urllib3.connection.VerifiedHTTPSConnection object at 0x000000000616A6D8>: Failed to establish a new connection: [Errno 11004] getaddrinfo failed')': /bot647382703:AAE-w7ZRzGoOopTtpiaAF40qlkHapWnMvBU/getUpdates\n",
      "2018-10-31 08:44:59,605 - telegram.vendor.ptb_urllib3.urllib3.connectionpool - WARNING - Retrying (Retry(total=0, connect=None, read=None, redirect=None)) after connection broken by 'NewConnectionError('<telegram.vendor.ptb_urllib3.urllib3.connection.VerifiedHTTPSConnection object at 0x0000000003EC8358>: Failed to establish a new connection: [Errno 11004] getaddrinfo failed')': /bot647382703:AAE-w7ZRzGoOopTtpiaAF40qlkHapWnMvBU/getUpdates\n",
      "2018-10-31 08:44:59,632 - telegram.ext.updater - ERROR - Error while getting Updates: urllib3 HTTPError HTTPSConnectionPool(host='api.telegram.org', port=443): Max retries exceeded with url: /bot647382703:AAE-w7ZRzGoOopTtpiaAF40qlkHapWnMvBU/getUpdates (Caused by NewConnectionError('<telegram.vendor.ptb_urllib3.urllib3.connection.VerifiedHTTPSConnection object at 0x0000000003EC8DD8>: Failed to establish a new connection: [Errno 11004] getaddrinfo failed'))\n",
      "2018-10-31 08:44:59,634 - __main__ - WARNING - Update \"None\" caused error \"urllib3 HTTPError HTTPSConnectionPool(host='api.telegram.org', port=443): Max retries exceeded with url: /bot647382703:AAE-w7ZRzGoOopTtpiaAF40qlkHapWnMvBU/getUpdates (Caused by NewConnectionError('<telegram.vendor.ptb_urllib3.urllib3.connection.VerifiedHTTPSConnection object at 0x0000000003EC8DD8>: Failed to establish a new connection: [Errno 11004] getaddrinfo failed'))\"\n"
     ]
    }
   ],
   "source": [
    "import logging\n",
    "from telegram import InlineKeyboardButton, InlineKeyboardMarkup\n",
    "from telegram.ext import Updater, CommandHandler, CallbackQueryHandler\n",
    "\n",
    "logging.basicConfig(format='%(asctime)s - %(name)s - %(levelname)s - %(message)s',\n",
    "                    level=logging.INFO)\n",
    "logger = logging.getLogger(__name__)\n",
    "\n",
    "\n",
    "def start(bot, update):\n",
    "    keyboard = [[InlineKeyboardButton(\"Parking\", callback_data='1')],\n",
    "                [InlineKeyboardButton(\"Housing\", callback_data='2')],\n",
    "                 [InlineKeyboardButton(\"Military Registration\", callback_data='3')],\n",
    "                  [InlineKeyboardButton(\"Residence life Staff\", callback_data='4')],\n",
    "                [InlineKeyboardButton(\"Resident Assistants/ Floor Represenatives\", callback_data='5')]]\n",
    "\n",
    "    reply_markup = InlineKeyboardMarkup(keyboard)\n",
    "\n",
    "    update.message.reply_text('Services covered by Residence Life unit:', reply_markup=reply_markup)\n",
    "\n",
    "\n",
    "def button(bot, update):\n",
    "    query = update.callback_query\n",
    "\n",
    "    bot.edit_message_text(text=\"Selected option: {}\".format(query.data),\n",
    "                          chat_id=query.message.chat_id,\n",
    "                          message_id=query.message.message_id)\n",
    "\n",
    "\n",
    "def help(bot, update):\n",
    "    update.message.reply_text(\"Use /start to test this bot.\")\n",
    "\n",
    "\n",
    "def error(bot, update, error):\n",
    "    \"\"\"Log Errors caused by Updates.\"\"\"\n",
    "    logger.warning('Update \"%s\" caused error \"%s\"', update, error)\n",
    "\n",
    "\n",
    "def main():\n",
    "    # Create the Updater and pass it your bot's token.\n",
    "    updater = Updater(\"647382703:AAE-w7ZRzGoOopTtpiaAF40qlkHapWnMvBU\")\n",
    "\n",
    "    updater.dispatcher.add_handler(CommandHandler('start', start))\n",
    "    updater.dispatcher.add_handler(CallbackQueryHandler(button))\n",
    "    updater.dispatcher.add_handler(CommandHandler('help', help))\n",
    "    updater.dispatcher.add_error_handler(error)\n",
    "\n",
    "    # Start the Bot\n",
    "    updater.start_polling()\n",
    "\n",
    "    # Run the bot until the user presses Ctrl-C or the process receives SIGINT,\n",
    "    # SIGTERM or SIGABRT\n",
    "    updater.idle()\n",
    "\n",
    "\n",
    "if __name__ == '__main__':\n",
    "    main()"
   ]
  },
  {
   "cell_type": "code",
   "execution_count": null,
   "metadata": {},
   "outputs": [],
   "source": []
  }
 ],
 "metadata": {
  "kernelspec": {
   "display_name": "Python 3",
   "language": "python",
   "name": "python3"
  },
  "language_info": {
   "codemirror_mode": {
    "name": "ipython",
    "version": 3
   },
   "file_extension": ".py",
   "mimetype": "text/x-python",
   "name": "python",
   "nbconvert_exporter": "python",
   "pygments_lexer": "ipython3",
   "version": "3.7.0"
  }
 },
 "nbformat": 4,
 "nbformat_minor": 2
}
